Invalid HTTP_HOST header: '127.0.0.1:8000'. You may need to add '127.0.0.1' to ALLOWED_HOSTS.
Bad Request: /create
HTTP GET /create 400 [0.35, 127.0.0.1:61468]
Invalid HTTP_HOST header: '127.0.0.1:8000'. You may need to add '127.0.0.1' to ALLOWED_HOSTS.
Bad Request: /
HTTP GET / 400 [0.09, 127.0.0.1:61468]
C:\Users\joni0\OneDrive\Desktop\brew_seminar\brew_seminar\brew_system\settings.py changed, reloading.
C:\Users\joni0\OneDrive\Desktop\brew_seminar\brew_seminar\brew_system\settings.py changed, reloading.
Invalid HTTP_HOST header: '127.0.0.1:8000'. You may need to add '127.0.0.1' to ALLOWED_HOSTS.
Bad Request: /
HTTP GET / 400 [0.25, 127.0.0.1:61562]
C:\Users\joni0\OneDrive\Desktop\brew_seminar\brew_seminar\brew_system\settings.py changed, reloading.
Invalid HTTP_HOST header: '127.0.0.1:8000'. You may need to add '127.0.0.1' to ALLOWED_HOSTS.
Bad Request: /
HTTP GET / 400 [0.35, 127.0.0.1:61726]
C:\Users\joni0\OneDrive\Desktop\brew_seminar\brew_seminar\brew_system\settings.py changed, reloading.
Invalid HTTP_HOST header: '127.0.0.1:8000'. You may need to add '127.0.0.1' to ALLOWED_HOSTS.
Bad Request: /create
HTTP GET /create 400 [0.17, 127.0.0.1:61773]
C:\Users\joni0\OneDrive\Desktop\brew_seminar\brew_seminar\brew_system\settings.py changed, reloading.
HTTP GET /create 200 [0.27, 127.0.0.1:61787]
HTTP GET /static/js/create.js 200 [0.46, 127.0.0.1:61788]
Not Found: /favicon.ico
Not Found: /creatze
Not Found: /favicon.ico
Not Found: /favicon.ico
Not Found: /ws/socket-server/
Not Found: /ws/socket-server/
[32mHTTP GET /home 302 [0.07, 127.0.0.1:47502][0m
[mHTTP GET /login 200 [0.04, 127.0.0.1:47502][0m
[32mHTTP POST /login 302 [1.42, 127.0.0.1:47502][0m
[mHTTP GET /home 200 [0.04, 127.0.0.1:47502][0m
[32mHTTP POST /brewing 302 [0.04, 127.0.0.1:47502][0m
[mHTTP GET /brewing 200 [0.95, 127.0.0.1:47502][0m
[mHTTP GET /static/js/protocol_csv.js 200 [0.03, 127.0.0.1:47502][0m
WebSocket HANDSHAKING /ws/socket-server/ [127.0.0.1:57694]
WebSocket CONNECT /ws/socket-server/ [127.0.0.1:57694]
Mon Nov 21 13:59:56 2022: Another client connected
[mHTTP GET /brewing 200 [0.10, 127.0.0.1:44758][0m
[32mHTTP POST /brewing 302 [0.05, 127.0.0.1:44758][0m
[mHTTP GET /brewing 200 [0.94, 127.0.0.1:44758][0m
[36mHTTP GET /static/js/protocol_csv.js 304 [0.01, 127.0.0.1:44758][0m
WebSocket HANDSHAKING /ws/socket-server/ [127.0.0.1:57002]
WebSocket CONNECT /ws/socket-server/ [127.0.0.1:57002]
Mon Nov 21 14:02:49 2022: Another client connected
/home/pi/pidjango/brew_system/brewing/process/hardware.py changed, reloading.
[mHTTP GET /brewing 200 [0.10, 127.0.0.1:50026][0m
[32mHTTP POST /brewing 302 [0.05, 127.0.0.1:50026][0m
[mHTTP GET /brewing 200 [0.91, 127.0.0.1:50026][0m
WebSocket HANDSHAKING /ws/socket-server/ [127.0.0.1:53074]
WebSocket CONNECT /ws/socket-server/ [127.0.0.1:53074]
Mon Nov 21 14:03:51 2022: Another client connected
/home/pi/pidjango/brew_system/brewing/process/hardware.py changed, reloading.
[mHTTP GET /brewing 200 [0.10, 127.0.0.1:37558][0m
[32mHTTP POST /brewing 302 [0.05, 127.0.0.1:37558][0m
[mHTTP GET /brewing 200 [0.99, 127.0.0.1:37558][0m
WebSocket HANDSHAKING /ws/socket-server/ [127.0.0.1:57830]
WebSocket CONNECT /ws/socket-server/ [127.0.0.1:57830]
Mon Nov 21 14:05:03 2022: Another client connected
[mHTTP GET /brewing 200 [0.08, 127.0.0.1:49432][0m
[32mHTTP POST /brewing 302 [0.04, 127.0.0.1:49432][0m
[mHTTP GET /brewing 200 [0.91, 127.0.0.1:49432][0m
[36mHTTP GET /static/js/protocol_csv.js 304 [0.01, 127.0.0.1:49432][0m
WebSocket HANDSHAKING /ws/socket-server/ [127.0.0.1:49446]
WebSocket CONNECT /ws/socket-server/ [127.0.0.1:49446]
Mon Nov 21 14:06:46 2022: Another client connected
[mHTTP GET /brewing 200 [0.07, 127.0.0.1:41964][0m
[32mHTTP POST /brewing 302 [0.05, 127.0.0.1:41964][0m
[mHTTP GET /brewing 200 [0.90, 127.0.0.1:41964][0m
WebSocket HANDSHAKING /ws/socket-server/ [127.0.0.1:54690]
WebSocket CONNECT /ws/socket-server/ [127.0.0.1:54690]
Mon Nov 21 14:07:42 2022: Another client connected
Exception inside application: module 'os' has no attribute 'sytsem'
Traceback (most recent call last):
  File "/home/pi/env/lib/python3.9/site-packages/channels/staticfiles.py", line 44, in __call__
    return await self.application(scope, receive, send)
  File "/home/pi/env/lib/python3.9/site-packages/channels/routing.py", line 71, in __call__
    return await application(scope, receive, send)
  File "/home/pi/env/lib/python3.9/site-packages/channels/sessions.py", line 47, in __call__
    return await self.inner(dict(scope, cookies=cookies), receive, send)
  File "/home/pi/env/lib/python3.9/site-packages/channels/sessions.py", line 263, in __call__
    return await self.inner(wrapper.scope, receive, wrapper.send)
  File "/home/pi/env/lib/python3.9/site-packages/channels/auth.py", line 185, in __call__
    return await super().__call__(scope, receive, send)
  File "/home/pi/env/lib/python3.9/site-packages/channels/middleware.py", line 26, in __call__
    return await self.inner(scope, receive, send)
  File "/home/pi/env/lib/python3.9/site-packages/channels/routing.py", line 150, in __call__
    return await application(
  File "/home/pi/env/lib/python3.9/site-packages/channels/consumer.py", line 94, in app
    return await consumer(scope, receive, send)
  File "/home/pi/env/lib/python3.9/site-packages/channels/consumer.py", line 58, in __call__
    await await_many_dispatch(
  File "/home/pi/env/lib/python3.9/site-packages/channels/utils.py", line 51, in await_many_dispatch
    await dispatch(result)
  File "/home/pi/env/lib/python3.9/site-packages/asgiref/sync.py", line 435, in __call__
    ret = await asyncio.wait_for(future, timeout=None)
  File "/usr/lib/python3.9/asyncio/tasks.py", line 442, in wait_for
    return await fut
  File "/usr/lib/python3.9/concurrent/futures/thread.py", line 52, in run
    result = self.fn(*self.args, **self.kwargs)
  File "/home/pi/env/lib/python3.9/site-packages/channels/db.py", line 13, in thread_handler
    return super().thread_handler(loop, *args, **kwargs)
  File "/home/pi/env/lib/python3.9/site-packages/asgiref/sync.py", line 476, in thread_handler
    return func(*args, **kwargs)
  File "/home/pi/env/lib/python3.9/site-packages/channels/consumer.py", line 125, in dispatch
    handler(message)
  File "/home/pi/env/lib/python3.9/site-packages/channels/generic/websocket.py", line 59, in websocket_receive
    self.receive(text_data=message["text"])
  File "/home/pi/pidjango/brew_system/brewing/consumer.py", line 24, in receive
    self.evaluate_response(text_data_json)
  File "/home/pi/pidjango/brew_system/brewing/consumer.py", line 52, in evaluate_response
    if(brew_system.next_step()):
  File "/home/pi/pidjango/brew_system/brewing/process/brew_server.py", line 96, in next_step
    self.initiate_maischen()
  File "/home/pi/pidjango/brew_system/brewing/process/brew_server.py", line 206, in initiate_maischen
    self.heat(int(json.loads(brew_recipe.objects.get(id=self.status["recipe"]).maischplan)[0][1]))
  File "/home/pi/pidjango/brew_system/brewing/process/brew_server.py", line 232, in heat
    self.hardware.heat_on()
  File "/home/pi/pidjango/brew_system/brewing/process/hardware.py", line 20, in heat_on
    os.sytsem("ls")
AttributeError: module 'os' has no attribute 'sytsem'
WebSocket DISCONNECT /ws/socket-server/ [127.0.0.1:54690]
/home/pi/pidjango/brew_system/brewing/process/hardware.py changed, reloading.
[mHTTP GET /brewing 200 [0.15, 127.0.0.1:42102][0m
[32mHTTP POST /brewing 302 [0.06, 127.0.0.1:42102][0m
[mHTTP GET /brewing 200 [0.98, 127.0.0.1:42102][0m
WebSocket HANDSHAKING /ws/socket-server/ [127.0.0.1:33956]
WebSocket CONNECT /ws/socket-server/ [127.0.0.1:33956]
Mon Nov 21 14:08:25 2022: Another client connected
[mHTTP GET /brewing 200 [0.07, 127.0.0.1:43910][0m
[32mHTTP POST /brewing 302 [0.03, 127.0.0.1:43910][0m
[mHTTP GET /brewing 200 [0.91, 127.0.0.1:43910][0m
[36mHTTP GET /static/js/protocol_csv.js 304 [0.01, 127.0.0.1:43910][0m
WebSocket HANDSHAKING /ws/socket-server/ [127.0.0.1:50836]
WebSocket CONNECT /ws/socket-server/ [127.0.0.1:50836]
Mon Nov 21 14:11:02 2022: Another client connected
Listen failure: Couldn't listen on 0.0.0.0:80: [Errno 98] Address already in use.
Invalid HTTP_HOST header: '10.31.150.207:10000'. You may need to add '10.31.150.207' to ALLOWED_HOSTS.
Bad Request: /
[31;1mHTTP GET / 400 [0.16, 10.31.0.44:51034][0m
Invalid HTTP_HOST header: '10.31.150.207:10000'. You may need to add '10.31.150.207' to ALLOWED_HOSTS.
Bad Request: /favicon.ico
[31;1mHTTP GET /favicon.ico 400 [0.16, 10.31.0.44:51034][0m
[mHTTP GET / 200 [0.07, 10.31.0.44:51052][0m
[mHTTP GET /static/css/style.css 200 [0.02, 10.31.0.44:51052][0m
[mHTTP GET /static/css/login.css 200 [0.01, 10.31.0.44:51052][0m
[mHTTP GET /static/css/create.css 200 [0.01, 10.31.0.44:51052][0m
[mHTTP GET /static/css/brewing.css 200 [0.01, 10.31.0.44:51052][0m
[mHTTP GET /static/css/home.css 200 [0.01, 10.31.0.44:51052][0m
[mHTTP GET /static/css/template.css 200 [0.01, 10.31.0.44:51052][0m
[mHTTP GET / 200 [0.03, 10.31.0.44:51052][0m
[mHTTP GET /static/img/beer_background.webm 200 [0.91, 10.31.0.44:51052][0m
[mHTTP GET /static/img/favicon.ico 200 [0.35, 10.31.0.44:51061][0m
[32mHTTP GET /home 302 [0.07, 10.31.0.44:51061][0m
[mHTTP GET /login 200 [0.04, 10.31.0.44:51061][0m
[32mHTTP POST /login 302 [0.67, 10.31.0.44:51061][0m
[mHTTP GET /home 200 [0.05, 10.31.0.44:51061][0m
[mHTTP GET /static/js/home.js 200 [0.01, 10.31.0.44:51061][0m
[mHTTP GET /static/js/home.js 200 [0.01, 10.31.0.44:51061][0m
[32mHTTP POST /brewing 302 [0.02, 10.31.0.44:51061][0m
[mHTTP GET /brewing 200 [1.00, 10.31.0.44:51061][0m
[mHTTP GET /static/js/three.js 200 [0.07, 10.31.0.44:51061][0m
[mHTTP GET /static/js/server_connection.js 200 [0.06, 10.31.0.44:51064][0m
[mHTTP GET /static/js/protocol_csv.js 200 [0.07, 10.31.0.44:51065][0m
[mHTTP GET /static/js/createPDF.js 200 [0.08, 10.31.0.44:51066][0m
[mHTTP GET /static/img/download.png 200 [0.09, 10.31.0.44:51067][0m
[mHTTP GET /static/js/protocol_csv.js 200 [0.01, 10.31.0.44:51067][0m
[mHTTP GET /static/js/server_connection.js 200 [0.01, 10.31.0.44:51064][0m
[mHTTP GET /static/js/createPDF.js 200 [0.01, 10.31.0.44:51061][0m
[mHTTP GET /static/js/three.js 200 [0.04, 10.31.0.44:51064][0m
WebSocket HANDSHAKING /ws/socket-server/ [10.31.0.44:51071]
WebSocket CONNECT /ws/socket-server/ [10.31.0.44:51071]
Mon Nov 21 14:16:03 2022: Another client connected
Exception inside application: brew_recipe matching query does not exist.
Traceback (most recent call last):
  File "/home/pi/env/lib/python3.9/site-packages/channels/staticfiles.py", line 44, in __call__
    return await self.application(scope, receive, send)
  File "/home/pi/env/lib/python3.9/site-packages/channels/routing.py", line 71, in __call__
    return await application(scope, receive, send)
  File "/home/pi/env/lib/python3.9/site-packages/channels/sessions.py", line 47, in __call__
    return await self.inner(dict(scope, cookies=cookies), receive, send)
  File "/home/pi/env/lib/python3.9/site-packages/channels/sessions.py", line 263, in __call__
    return await self.inner(wrapper.scope, receive, wrapper.send)
  File "/home/pi/env/lib/python3.9/site-packages/channels/auth.py", line 185, in __call__
    return await super().__call__(scope, receive, send)
  File "/home/pi/env/lib/python3.9/site-packages/channels/middleware.py", line 26, in __call__
    return await self.inner(scope, receive, send)
  File "/home/pi/env/lib/python3.9/site-packages/channels/routing.py", line 150, in __call__
    return await application(
  File "/home/pi/env/lib/python3.9/site-packages/channels/consumer.py", line 94, in app
    return await consumer(scope, receive, send)
  File "/home/pi/env/lib/python3.9/site-packages/channels/consumer.py", line 58, in __call__
    await await_many_dispatch(
  File "/home/pi/env/lib/python3.9/site-packages/channels/utils.py", line 51, in await_many_dispatch
    await dispatch(result)
  File "/home/pi/env/lib/python3.9/site-packages/asgiref/sync.py", line 435, in __call__
    ret = await asyncio.wait_for(future, timeout=None)
  File "/usr/lib/python3.9/asyncio/tasks.py", line 442, in wait_for
    return await fut
  File "/usr/lib/python3.9/concurrent/futures/thread.py", line 52, in run
    result = self.fn(*self.args, **self.kwargs)
  File "/home/pi/env/lib/python3.9/site-packages/channels/db.py", line 13, in thread_handler
    return super().thread_handler(loop, *args, **kwargs)
  File "/home/pi/env/lib/python3.9/site-packages/asgiref/sync.py", line 476, in thread_handler
    return func(*args, **kwargs)
  File "/home/pi/env/lib/python3.9/site-packages/channels/consumer.py", line 125, in dispatch
    handler(message)
  File "/home/pi/env/lib/python3.9/site-packages/channels/generic/websocket.py", line 59, in websocket_receive
    self.receive(text_data=message["text"])
  File "/home/pi/pidjango/brew_system/brewing/consumer.py", line 24, in receive
    self.evaluate_response(text_data_json)
  File "/home/pi/pidjango/brew_system/brewing/consumer.py", line 80, in evaluate_response
    rec = brew_recipe.objects.get(id=int(msg["message"]))
  File "/home/pi/env/lib/python3.9/site-packages/django/db/models/manager.py", line 85, in manager_method
    return getattr(self.get_queryset(), name)(*args, **kwargs)
  File "/home/pi/env/lib/python3.9/site-packages/django/db/models/query.py", line 496, in get
    raise self.model.DoesNotExist(
brewing.models.brew_recipe.DoesNotExist: brew_recipe matching query does not exist.
WebSocket DISCONNECT /ws/socket-server/ [10.31.0.44:51071]
[mHTTP GET /brewing 200 [0.98, 10.31.0.44:51064][0m
WebSocket HANDSHAKING /ws/socket-server/ [10.31.0.44:51072]
WebSocket CONNECT /ws/socket-server/ [10.31.0.44:51072]
Mon Nov 21 14:16:26 2022: Another client connected
Exception inside application: brew_recipe matching query does not exist.
Traceback (most recent call last):
  File "/home/pi/env/lib/python3.9/site-packages/channels/staticfiles.py", line 44, in __call__
    return await self.application(scope, receive, send)
  File "/home/pi/env/lib/python3.9/site-packages/channels/routing.py", line 71, in __call__
    return await application(scope, receive, send)
  File "/home/pi/env/lib/python3.9/site-packages/channels/sessions.py", line 47, in __call__
    return await self.inner(dict(scope, cookies=cookies), receive, send)
  File "/home/pi/env/lib/python3.9/site-packages/channels/sessions.py", line 263, in __call__
    return await self.inner(wrapper.scope, receive, wrapper.send)
  File "/home/pi/env/lib/python3.9/site-packages/channels/auth.py", line 185, in __call__
    return await super().__call__(scope, receive, send)
  File "/home/pi/env/lib/python3.9/site-packages/channels/middleware.py", line 26, in __call__
    return await self.inner(scope, receive, send)
  File "/home/pi/env/lib/python3.9/site-packages/channels/routing.py", line 150, in __call__
    return await application(
  File "/home/pi/env/lib/python3.9/site-packages/channels/consumer.py", line 94, in app
    return await consumer(scope, receive, send)
  File "/home/pi/env/lib/python3.9/site-packages/channels/consumer.py", line 58, in __call__
    await await_many_dispatch(
  File "/home/pi/env/lib/python3.9/site-packages/channels/utils.py", line 51, in await_many_dispatch
    await dispatch(result)
  File "/home/pi/env/lib/python3.9/site-packages/asgiref/sync.py", line 435, in __call__
    ret = await asyncio.wait_for(future, timeout=None)
  File "/usr/lib/python3.9/asyncio/tasks.py", line 442, in wait_for
    return await fut
  File "/usr/lib/python3.9/concurrent/futures/thread.py", line 52, in run
    result = self.fn(*self.args, **self.kwargs)
  File "/home/pi/env/lib/python3.9/site-packages/channels/db.py", line 13, in thread_handler
    return super().thread_handler(loop, *args, **kwargs)
  File "/home/pi/env/lib/python3.9/site-packages/asgiref/sync.py", line 476, in thread_handler
    return func(*args, **kwargs)
  File "/home/pi/env/lib/python3.9/site-packages/channels/consumer.py", line 125, in dispatch
    handler(message)
  File "/home/pi/env/lib/python3.9/site-packages/channels/generic/websocket.py", line 59, in websocket_receive
    self.receive(text_data=message["text"])
  File "/home/pi/pidjango/brew_system/brewing/consumer.py", line 24, in receive
    self.evaluate_response(text_data_json)
  File "/home/pi/pidjango/brew_system/brewing/consumer.py", line 80, in evaluate_response
    rec = brew_recipe.objects.get(id=int(msg["message"]))
  File "/home/pi/env/lib/python3.9/site-packages/django/db/models/manager.py", line 85, in manager_method
    return getattr(self.get_queryset(), name)(*args, **kwargs)
  File "/home/pi/env/lib/python3.9/site-packages/django/db/models/query.py", line 496, in get
    raise self.model.DoesNotExist(
brewing.models.brew_recipe.DoesNotExist: brew_recipe matching query does not exist.
WebSocket DISCONNECT /ws/socket-server/ [10.31.0.44:51072]
/home/pi/pidjango/brew_system/brew_system/settings.py changed, reloading.
[mHTTP GET /brewing 200 [0.12, 10.31.0.44:51267][0m
[36mHTTP GET /static/css/style.css 304 [0.02, 10.31.0.44:51267][0m
[36mHTTP GET /static/js/home.js 304 [0.01, 10.31.0.44:51269][0m
[36mHTTP GET /static/js/home.js 304 [0.00, 10.31.0.44:51269][0m
[36mHTTP GET /static/css/login.css 304 [0.00, 10.31.0.44:51269][0m
[36mHTTP GET /static/css/create.css 304 [0.00, 10.31.0.44:51269][0m
[36mHTTP GET /static/css/brewing.css 304 [0.01, 10.31.0.44:51269][0m
[36mHTTP GET /static/css/home.css 304 [0.02, 10.31.0.44:51269][0m
[36mHTTP GET /static/css/template.css 304 [0.01, 10.31.0.44:51269][0m
[36mHTTP GET /static/img/favicon.ico 304 [0.02, 10.31.0.44:51269][0m
[32mHTTP POST /brewing 302 [0.07, 10.31.0.44:51269][0m
[mHTTP GET /brewing 200 [0.95, 10.31.0.44:51269][0m
[36mHTTP GET /static/js/three.js 304 [0.02, 10.31.0.44:51269][0m
[36mHTTP GET /static/js/server_connection.js 304 [0.02, 10.31.0.44:51267][0m
[36mHTTP GET /static/js/protocol_csv.js 304 [0.01, 10.31.0.44:51274][0m
[36mHTTP GET /static/img/download.png 304 [0.02, 10.31.0.44:51275][0m
[36mHTTP GET /static/js/createPDF.js 304 [0.03, 10.31.0.44:51276][0m
WebSocket HANDSHAKING /ws/socket-server/ [10.31.0.44:51277]
WebSocket CONNECT /ws/socket-server/ [10.31.0.44:51277]
Mon Nov 21 14:22:01 2022: Another client connected
[mHTTP GET / 200 [0.09, 10.31.0.165:61078][0m
[mHTTP GET /static/css/style.css 200 [0.03, 10.31.0.165:61078][0m
[mHTTP GET /static/css/login.css 200 [0.01, 10.31.0.165:61078][0m
[mHTTP GET /static/css/create.css 200 [0.02, 10.31.0.165:61078][0m
[mHTTP GET /static/css/brewing.css 200 [0.01, 10.31.0.165:61078][0m
[mHTTP GET /static/css/home.css 200 [0.01, 10.31.0.165:61078][0m
[mHTTP GET /static/css/template.css 200 [0.01, 10.31.0.165:61078][0m
[mHTTP GET /static/img/beer_background.webm 200 [0.48, 10.31.0.165:61078][0m
[mHTTP GET /static/img/favicon.ico 200 [0.01, 10.31.0.165:61091][0m
[32mHTTP GET /home 302 [0.04, 10.31.0.165:61091][0m
[mHTTP GET /login 200 [0.03, 10.31.0.165:61091][0m
[32mHTTP POST /login 302 [0.67, 10.31.0.165:61091][0m
[mHTTP GET /home 200 [0.04, 10.31.0.165:61091][0m
[mHTTP GET /static/js/home.js 200 [0.01, 10.31.0.165:61091][0m
[32mHTTP POST /brewing 302 [0.04, 10.31.0.165:61091][0m
[mHTTP GET /brewing 200 [0.93, 10.31.0.165:61091][0m
[mHTTP GET /static/img/download.png 200 [0.01, 10.31.0.165:61091][0m
[mHTTP GET /static/js/three.js 200 [0.03, 10.31.0.165:61091][0m
[mHTTP GET /static/js/server_connection.js 200 [0.01, 10.31.0.165:61112][0m
[mHTTP GET /static/js/protocol_csv.js 200 [0.02, 10.31.0.165:61113][0m
[mHTTP GET /static/js/createPDF.js 200 [0.02, 10.31.0.165:61114][0m
WebSocket HANDSHAKING /ws/socket-server/ [10.31.0.165:61117]
WebSocket CONNECT /ws/socket-server/ [10.31.0.165:61117]
Mon Nov 21 14:30:11 2022: Another client connected
Exception inside application: brew_recipe matching query does not exist.
Traceback (most recent call last):
  File "/home/pi/env/lib/python3.9/site-packages/channels/staticfiles.py", line 44, in __call__
    return await self.application(scope, receive, send)
  File "/home/pi/env/lib/python3.9/site-packages/channels/routing.py", line 71, in __call__
    return await application(scope, receive, send)
  File "/home/pi/env/lib/python3.9/site-packages/channels/sessions.py", line 47, in __call__
    return await self.inner(dict(scope, cookies=cookies), receive, send)
  File "/home/pi/env/lib/python3.9/site-packages/channels/sessions.py", line 263, in __call__
    return await self.inner(wrapper.scope, receive, wrapper.send)
  File "/home/pi/env/lib/python3.9/site-packages/channels/auth.py", line 185, in __call__
    return await super().__call__(scope, receive, send)
  File "/home/pi/env/lib/python3.9/site-packages/channels/middleware.py", line 26, in __call__
    return await self.inner(scope, receive, send)
  File "/home/pi/env/lib/python3.9/site-packages/channels/routing.py", line 150, in __call__
    return await application(
  File "/home/pi/env/lib/python3.9/site-packages/channels/consumer.py", line 94, in app
    return await consumer(scope, receive, send)
  File "/home/pi/env/lib/python3.9/site-packages/channels/consumer.py", line 58, in __call__
    await await_many_dispatch(
  File "/home/pi/env/lib/python3.9/site-packages/channels/utils.py", line 51, in await_many_dispatch
    await dispatch(result)
  File "/home/pi/env/lib/python3.9/site-packages/asgiref/sync.py", line 435, in __call__
    ret = await asyncio.wait_for(future, timeout=None)
  File "/usr/lib/python3.9/asyncio/tasks.py", line 442, in wait_for
    return await fut
  File "/usr/lib/python3.9/concurrent/futures/thread.py", line 52, in run
    result = self.fn(*self.args, **self.kwargs)
  File "/home/pi/env/lib/python3.9/site-packages/channels/db.py", line 13, in thread_handler
    return super().thread_handler(loop, *args, **kwargs)
  File "/home/pi/env/lib/python3.9/site-packages/asgiref/sync.py", line 476, in thread_handler
    return func(*args, **kwargs)
  File "/home/pi/env/lib/python3.9/site-packages/channels/consumer.py", line 125, in dispatch
    handler(message)
  File "/home/pi/env/lib/python3.9/site-packages/channels/generic/websocket.py", line 59, in websocket_receive
    self.receive(text_data=message["text"])
  File "/home/pi/pidjango/brew_system/brewing/consumer.py", line 24, in receive
    self.evaluate_response(text_data_json)
  File "/home/pi/pidjango/brew_system/brewing/consumer.py", line 80, in evaluate_response
    rec = brew_recipe.objects.get(id=int(msg["message"]))
  File "/home/pi/env/lib/python3.9/site-packages/django/db/models/manager.py", line 85, in manager_method
    return getattr(self.get_queryset(), name)(*args, **kwargs)
  File "/home/pi/env/lib/python3.9/site-packages/django/db/models/query.py", line 496, in get
    raise self.model.DoesNotExist(
brewing.models.brew_recipe.DoesNotExist: brew_recipe matching query does not exist.
WebSocket DISCONNECT /ws/socket-server/ [10.31.0.165:61117]
[mHTTP GET /create 200 [0.07, 10.31.0.165:61131][0m
[mHTTP GET /static/js/create.js 200 [0.02, 10.31.0.165:61131][0m
Not Found: /favicon.ico
Internal Server Error: /brewing
Traceback (most recent call last):
  File "/home/pi/pidjango/djenv/lib/python3.9/site-packages/django/core/handlers/exception.py", line 55, in inner
    response = get_response(request)
  File "/home/pi/pidjango/djenv/lib/python3.9/site-packages/django/core/handlers/base.py", line 197, in _get_response
    response = wrapped_callback(request, *callback_args, **callback_kwargs)
  File "/home/pi/pidjango/brew_system/brewing/views.py", line 98, in brewing
    "status": brew_system.get_status(),
  File "/home/pi/pidjango/brew_system/brewing/process/brew_server.py", line 57, in get_status
    "temperature": self.hardware.get_temp(),
  File "/home/pi/pidjango/brew_system/brewing/process/hardware.py", line 10, in get_temp
    tempfile = open("/sys/bus/w1/devices/28-00000d5d9de2/w1_slave")
FileNotFoundError: [Errno 2] No such file or directory: '/sys/bus/w1/devices/28-00000d5d9de2/w1_slave'
Internal Server Error: /brewing
Traceback (most recent call last):
  File "/home/pi/pidjango/djenv/lib/python3.9/site-packages/django/core/handlers/exception.py", line 55, in inner
    response = get_response(request)
  File "/home/pi/pidjango/djenv/lib/python3.9/site-packages/django/core/handlers/base.py", line 197, in _get_response
    response = wrapped_callback(request, *callback_args, **callback_kwargs)
  File "/home/pi/pidjango/brew_system/brewing/views.py", line 98, in brewing
    "status": brew_system.get_status(),
  File "/home/pi/pidjango/brew_system/brewing/process/brew_server.py", line 57, in get_status
    "temperature": self.hardware.get_temp(),
  File "/home/pi/pidjango/brew_system/brewing/process/hardware.py", line 10, in get_temp
    tempfile = open("/sys/bus/w1/devices/28-00000d5d9de2/w1_slave")
FileNotFoundError: [Errno 2] No such file or directory: '/sys/bus/w1/devices/28-00000d5d9de2/w1_slave'
Internal Server Error: /brewing
Traceback (most recent call last):
  File "/home/pi/pidjango/djenv/lib/python3.9/site-packages/django/core/handlers/exception.py", line 55, in inner
    response = get_response(request)
  File "/home/pi/pidjango/djenv/lib/python3.9/site-packages/django/core/handlers/base.py", line 197, in _get_response
    response = wrapped_callback(request, *callback_args, **callback_kwargs)
  File "/home/pi/pidjango/brew_system/brewing/views.py", line 98, in brewing
    "status": brew_system.get_status(),
  File "/home/pi/pidjango/brew_system/brewing/process/brew_server.py", line 57, in get_status
    "temperature": self.hardware.get_temp(),
  File "/home/pi/pidjango/brew_system/brewing/process/hardware.py", line 10, in get_temp
    tempfile = open("/sys/bus/w1/devices/28-00000d5d9de2/w1_slave")
FileNotFoundError: [Errno 2] No such file or directory: '/sys/bus/w1/devices/28-00000d5d9de2/w1_slave'
Not Found: /ws/socket-server/
Not Found: /ws/socket-server/
HTTP GET /brewing 200 [1.15, 10.31.0.44:63530]
HTTP POST /brewing 302 [0.05, 10.31.0.44:63530]
HTTP GET /brewing 200 [0.88, 10.31.0.44:63530]
WebSocket HANDSHAKING /ws/socket-server/ [10.31.0.44:63538]
WebSocket CONNECT /ws/socket-server/ [10.31.0.44:63538]
Mon Nov 28 14:17:59 2022: Another client connected
HTTP GET / 200 [0.06, 10.31.0.44:63708]
Application instance <Task pending name='Task-38' coro=<StaticFilesWrapper.__call__() running at /home/pi/env/lib/python3.9/site-packages/channels/staticfiles.py:40> wait_for=<Future pending cb=[_chain_future.<locals>._call_check_cancel() at /usr/lib/python3.9/asyncio/futures.py:384, <TaskWakeupMethWrapper object at 0xb3fa0b38>()]>> for connection <WebRequest at 0xb3580be0 method=GET uri=/static/img/beer_background.webm clientproto=HTTP/1.1> took too long to shut down and was killed.
HTTP GET /brewing 200 [0.91, 10.31.0.44:63754]
WebSocket DISCONNECT /ws/socket-server/ [10.31.0.44:63538]
WebSocket HANDSHAKING /ws/socket-server/ [10.31.0.44:63757]
HTTP GET /brewing 200 [0.90, 10.31.0.44:63754]
WebSocket DISCONNECT /ws/socket-server/ [10.31.0.44:63757]
WebSocket HANDSHAKING /ws/socket-server/ [10.31.0.44:63758]
HTTP GET /home 200 [0.08, 10.31.0.44:63754]
WebSocket DISCONNECT /ws/socket-server/ [10.31.0.44:63758]
HTTP POST /brewing 302 [0.03, 10.31.0.44:63754]
HTTP GET /brewing 200 [0.94, 10.31.0.44:63754]
Application instance <Task pending name='Task-4' coro=<StaticFilesWrapper.__call__() running at /home/pi/env/lib/python3.9/site-packages/channels/staticfiles.py:44> wait_for=<Future pending cb=[_chain_future.<locals>._call_check_cancel() at /usr/lib/python3.9/asyncio/futures.py:384, <TaskWakeupMethWrapper object at 0xb3f96520>()]>> for connection <WebSocketProtocol client=['10.31.0.44', 63538] path=b'/ws/socket-server/'> took too long to shut down and was killed.
WebSocket HANDSHAKING /ws/socket-server/ [10.31.0.44:63764]
Application instance <Task pending name='Task-40' coro=<StaticFilesWrapper.__call__() running at /home/pi/env/lib/python3.9/site-packages/channels/staticfiles.py:44> wait_for=<Future pending cb=[_chain_future.<locals>._call_check_cancel() at /usr/lib/python3.9/asyncio/futures.py:384, <TaskWakeupMethWrapper object at 0xb3f96b80>()]>> for connection <WebSocketProtocol client=['10.31.0.44', 63757] path=b'/ws/socket-server/'> took too long to shut down and was killed.
WebSocket DISCONNECT /ws/socket-server/ [10.31.0.44:63764]
Application instance <Task pending name='Task-42' coro=<StaticFilesWrapper.__call__() running at /home/pi/env/lib/python3.9/site-packages/channels/staticfiles.py:44> wait_for=<Future pending cb=[_chain_future.<locals>._call_check_cancel() at /usr/lib/python3.9/asyncio/futures.py:384, <TaskWakeupMethWrapper object at 0xb3f79b20>()]>> for connection <WebSocketProtocol client=['10.31.0.44', 63758] path=b'/ws/socket-server/'> took too long to shut down and was killed.
Application instance <Task pending name='Task-46' coro=<StaticFilesWrapper.__call__() running at /home/pi/env/lib/python3.9/site-packages/channels/staticfiles.py:44> wait_for=<Future pending cb=[_chain_future.<locals>._call_check_cancel() at /usr/lib/python3.9/asyncio/futures.py:384, <TaskWakeupMethWrapper object at 0xb35e81a8>()]>> for connection <WebSocketProtocol client=['10.31.0.44', 63764] path=b'/ws/socket-server/'> took too long to shut down and was killed.
/home/pi/pidjango/brew_system/brewing/process/hardware.py changed, reloading.
HTTP GET / 200 [0.05, 10.31.0.44:63962]
HTTP GET /static/img/beer_background.webm 200 [1.41, 10.31.0.44:63962]
HTTP GET /home 200 [0.08, 10.31.0.44:63970]
HTTP POST /brewing 302 [0.04, 10.31.0.44:63970]
HTTP GET /brewing 200 [0.97, 10.31.0.44:63970]
WebSocket HANDSHAKING /ws/socket-server/ [10.31.0.44:63976]
WebSocket CONNECT /ws/socket-server/ [10.31.0.44:63976]
Mon Nov 28 14:30:52 2022: Another client connected
HTTP GET /admin/brewing/brew_recipe/5/change/ 200 [0.38, 10.31.0.44:64036]
HTTP GET /admin/jsi18n/ 200 [0.02, 10.31.0.44:64036]
HTTP POST /admin/brewing/brew_recipe/5/change/ 302 [0.05, 10.31.0.44:64072]
HTTP GET /admin/brewing/brew_recipe/5/change/ 200 [0.34, 10.31.0.44:64072]
HTTP GET /admin/jsi18n/ 200 [0.02, 10.31.0.44:64072]
Invalid HTTP_HOST header: '127.0.0.1:8000'. You may need to add '127.0.0.1' to ALLOWED_HOSTS.
Traceback (most recent call last):
  File "/home/codespace/.local/lib/python3.10/site-packages/django/core/handlers/exception.py", line 55, in inner
    response = get_response(request)
  File "/home/codespace/.local/lib/python3.10/site-packages/django/utils/deprecation.py", line 135, in __call__
    response = self.process_request(request)
  File "/home/codespace/.local/lib/python3.10/site-packages/django/middleware/common.py", line 48, in process_request
    host = request.get_host()
  File "/home/codespace/.local/lib/python3.10/site-packages/django/http/request.py", line 148, in get_host
    raise DisallowedHost(msg)
django.core.exceptions.DisallowedHost: Invalid HTTP_HOST header: '127.0.0.1:8000'. You may need to add '127.0.0.1' to ALLOWED_HOSTS.
Bad Request: /
Internal Server Error: /brewing
Traceback (most recent call last):
  File "/home/codespace/.local/lib/python3.10/site-packages/django/core/handlers/exception.py", line 55, in inner
    response = get_response(request)
  File "/home/codespace/.local/lib/python3.10/site-packages/django/core/handlers/base.py", line 197, in _get_response
    response = wrapped_callback(request, *callback_args, **callback_kwargs)
  File "/workspaces/brew_seminar/brewing/views.py", line 98, in brewing
    "status": brew_system.get_status(),
  File "/workspaces/brew_seminar/brewing/process/brew_server.py", line 57, in get_status
    "temperature": self.hardware.get_temp(),
  File "/workspaces/brew_seminar/brewing/process/hardware.py", line 10, in get_temp
    tempfile = open("/sys/bus/w1/devices/28-00000d5d9de2/w1_slave")
FileNotFoundError: [Errno 2] No such file or directory: '/sys/bus/w1/devices/28-00000d5d9de2/w1_slave'
Not Found: /favicon.ico
/workspaces/brew_seminar/brewing/process/hardware.py changed, reloading.
Not Found: /ws/socket-server/
Not Found: /ws/socket-server/
/workspaces/brew_seminar/brewing/process/brew_server.py changed, reloading.
